Traceback (most recent call last):
  File "C:\Users\ASUS\AppData\Local\Programs\Python\Python39\lib\site-packages\jupyter_cache\executors\utils.py", line 51, in single_nb_execution
    executenb(
  File "C:\Users\ASUS\AppData\Local\Programs\Python\Python39\lib\site-packages\nbclient\client.py", line 1204, in execute
    return NotebookClient(nb=nb, resources=resources, km=km, **kwargs).execute()
  File "C:\Users\ASUS\AppData\Local\Programs\Python\Python39\lib\site-packages\nbclient\util.py", line 84, in wrapped
    return just_run(coro(*args, **kwargs))
  File "C:\Users\ASUS\AppData\Local\Programs\Python\Python39\lib\site-packages\nbclient\util.py", line 62, in just_run
    return loop.run_until_complete(coro)
  File "C:\Users\ASUS\AppData\Local\Programs\Python\Python39\lib\asyncio\base_events.py", line 642, in run_until_complete
    return future.result()
  File "C:\Users\ASUS\AppData\Local\Programs\Python\Python39\lib\site-packages\nbclient\client.py", line 663, in async_execute
    await self.async_execute_cell(
  File "C:\Users\ASUS\AppData\Local\Programs\Python\Python39\lib\site-packages\nbclient\client.py", line 965, in async_execute_cell
    await self._check_raise_for_error(cell, cell_index, exec_reply)
  File "C:\Users\ASUS\AppData\Local\Programs\Python\Python39\lib\site-packages\nbclient\client.py", line 862, in _check_raise_for_error
    raise CellExecutionError.from_cell_and_msg(cell, exec_reply_content)
nbclient.exceptions.CellExecutionError: An error occurred while executing the following cell:
------------------
#mengambil data tertentu dari website
p.find_all('article', {'class', 'articles--iridescent-list--item articles--iridescent-list--text-item'})
------------------

[1;31m---------------------------------------------------------------------------[0m
[1;31mAttributeError[0m                            Traceback (most recent call last)
[1;32m~\AppData\Local\Temp/ipykernel_9780/2216499110.py[0m in [0;36m<module>[1;34m[0m
[0;32m      1[0m [1;31m#mengambil data tertentu dari website[0m[1;33m[0m[1;33m[0m[1;33m[0m[0m
[1;32m----> 2[1;33m [0mp[0m[1;33m.[0m[0mfind_all[0m[1;33m([0m[1;34m'article'[0m[1;33m,[0m [1;33m{[0m[1;34m'class'[0m[1;33m,[0m [1;34m'articles--iridescent-list--item articles--iridescent-list--text-item'[0m[1;33m}[0m[1;33m)[0m[1;33m[0m[1;33m[0m[0m
[0m
[1;32m~\AppData\Local\Programs\Python\Python39\lib\site-packages\bs4\element.py[0m in [0;36m__getattr__[1;34m(self, key)[0m
[0;32m   2251[0m     [1;32mdef[0m [0m__getattr__[0m[1;33m([0m[0mself[0m[1;33m,[0m [0mkey[0m[1;33m)[0m[1;33m:[0m[1;33m[0m[1;33m[0m[0m
[0;32m   2252[0m         [1;34m"""Raise a helpful exception to explain a common code fix."""[0m[1;33m[0m[1;33m[0m[0m
[1;32m-> 2253[1;33m         raise AttributeError(
[0m[0;32m   2254[0m             [1;34m"ResultSet object has no attribute '%s'. You're probably treating a list of elements like a single element. Did you call find_all() when you meant to call find()?"[0m [1;33m%[0m [0mkey[0m[1;33m[0m[1;33m[0m[0m
[0;32m   2255[0m         )

[1;31mAttributeError[0m: ResultSet object has no attribute 'find_all'. You're probably treating a list of elements like a single element. Did you call find_all() when you meant to call find()?
AttributeError: ResultSet object has no attribute 'find_all'. You're probably treating a list of elements like a single element. Did you call find_all() when you meant to call find()?

